[2025-04-17T16:27:45.306+0000] {local_task_job_runner.py:123} INFO - ::group::Pre task execution logs
[2025-04-17T16:27:45.329+0000] {taskinstance.py:2614} INFO - Dependencies all met for dep_context=non-requeueable deps ti=<TaskInstance: csv_to_fhir_pipeline.transform_csv_to_fhir manual__2025-04-17T16:27:40.334621+00:00 [queued]>
[2025-04-17T16:27:45.341+0000] {taskinstance.py:2614} INFO - Dependencies all met for dep_context=requeueable deps ti=<TaskInstance: csv_to_fhir_pipeline.transform_csv_to_fhir manual__2025-04-17T16:27:40.334621+00:00 [queued]>
[2025-04-17T16:27:45.343+0000] {taskinstance.py:2867} INFO - Starting attempt 1 of 1
[2025-04-17T16:27:45.358+0000] {taskinstance.py:2890} INFO - Executing <Task(PythonOperator): transform_csv_to_fhir> on 2025-04-17 16:27:40.334621+00:00
[2025-04-17T16:27:45.369+0000] {warnings.py:112} WARNING - /home/***/.local/lib/python3.12/site-packages/***/task/task_runner/standard_task_runner.py:70: DeprecationWarning: This process (pid=485) is multi-threaded, use of fork() may lead to deadlocks in the child.
  pid = os.fork()

[2025-04-17T16:27:45.372+0000] {standard_task_runner.py:72} INFO - Started process 487 to run task
[2025-04-17T16:27:45.372+0000] {standard_task_runner.py:104} INFO - Running: ['***', 'tasks', 'run', 'csv_to_fhir_pipeline', 'transform_csv_to_fhir', 'manual__2025-04-17T16:27:40.334621+00:00', '--job-id', '39', '--raw', '--subdir', 'DAGS_FOLDER/csv_to_fhir_dag.py', '--cfg-path', '/tmp/tmp8yljki6b']
[2025-04-17T16:27:45.374+0000] {standard_task_runner.py:105} INFO - Job 39: Subtask transform_csv_to_fhir
[2025-04-17T16:27:45.437+0000] {task_command.py:467} INFO - Running <TaskInstance: csv_to_fhir_pipeline.transform_csv_to_fhir manual__2025-04-17T16:27:40.334621+00:00 [running]> on host 150b3182c96d
[2025-04-17T16:27:45.551+0000] {taskinstance.py:3134} INFO - Exporting env vars: AIRFLOW_CTX_DAG_OWNER='***' AIRFLOW_CTX_DAG_ID='csv_to_fhir_pipeline' AIRFLOW_CTX_TASK_ID='transform_csv_to_fhir' AIRFLOW_CTX_EXECUTION_DATE='2025-04-17T16:27:40.334621+00:00' AIRFLOW_CTX_TRY_NUMBER='1' AIRFLOW_CTX_DAG_RUN_ID='manual__2025-04-17T16:27:40.334621+00:00'
[2025-04-17T16:27:45.570+0000] {logging_mixin.py:190} INFO - Task instance is in running state
[2025-04-17T16:27:45.578+0000] {logging_mixin.py:190} INFO -  Previous state of the Task instance: queued
[2025-04-17T16:27:45.584+0000] {logging_mixin.py:190} INFO - Current task name:transform_csv_to_fhir state:running start_date:2025-04-17 16:27:45.331060+00:00
[2025-04-17T16:27:45.591+0000] {logging_mixin.py:190} INFO - Dag name:csv_to_fhir_pipeline and current dag run status:running
[2025-04-17T16:27:45.597+0000] {taskinstance.py:732} INFO - ::endgroup::
[2025-04-17T16:27:46.119+0000] {taskinstance.py:3313} ERROR - Task failed with exception
Traceback (most recent call last):
  File "/home/airflow/.local/lib/python3.12/site-packages/airflow/models/taskinstance.py", line 768, in _execute_task
    result = _execute_callable(context=context, **execute_callable_kwargs)
             ^^^^^^^^^^^^^^^^^^^^^^^^^^^^^^^^^^^^^^^^^^^^^^^^^^^^^^^^^^^^^
  File "/home/airflow/.local/lib/python3.12/site-packages/airflow/models/taskinstance.py", line 734, in _execute_callable
    return ExecutionCallableRunner(
           ^^^^^^^^^^^^^^^^^^^^^^^^
  File "/home/airflow/.local/lib/python3.12/site-packages/airflow/utils/operator_helpers.py", line 252, in run
    return self.func(*args, **kwargs)
           ^^^^^^^^^^^^^^^^^^^^^^^^^^
  File "/home/airflow/.local/lib/python3.12/site-packages/airflow/models/baseoperator.py", line 424, in wrapper
    return func(self, *args, **kwargs)
           ^^^^^^^^^^^^^^^^^^^^^^^^^^^
  File "/home/airflow/.local/lib/python3.12/site-packages/airflow/operators/python.py", line 238, in execute
    return_value = self.execute_callable()
                   ^^^^^^^^^^^^^^^^^^^^^^^
  File "/home/airflow/.local/lib/python3.12/site-packages/airflow/operators/python.py", line 256, in execute_callable
    return runner.run(*self.op_args, **self.op_kwargs)
           ^^^^^^^^^^^^^^^^^^^^^^^^^^^^^^^^^^^^^^^^^^^
  File "/home/airflow/.local/lib/python3.12/site-packages/airflow/utils/operator_helpers.py", line 252, in run
    return self.func(*args, **kwargs)
           ^^^^^^^^^^^^^^^^^^^^^^^^^^
  File "/opt/airflow/dags/scripts/transform_csv_to_fhir.py", line 87, in csv_to_fhir
    claim = Claim()
            ^^^^^^^
  File "/home/airflow/.local/lib/python3.12/site-packages/fhir/resources/core/fhirabstractmodel.py", line 105, in __init__
    BaseModel.__init__(__pydantic_self__, **data)
  File "/home/airflow/.local/lib/python3.12/site-packages/pydantic/v1/main.py", line 341, in __init__
    raise validation_error
pydantic.v1.error_wrappers.ValidationError: 3 validation errors for Claim
__root__ -> created
  field required (type=value_error.missing)
__root__ -> status
  field required (type=value_error.missing)
__root__ -> use
  field required (type=value_error.missing)
[2025-04-17T16:27:46.138+0000] {logging_mixin.py:190} INFO - Task instance in failure state
[2025-04-17T16:27:46.139+0000] {logging_mixin.py:190} INFO - Task start:2025-04-17 16:27:45.331060+00:00 end:2025-04-17 16:27:46.137775+00:00 duration:0.806715
[2025-04-17T16:27:46.140+0000] {logging_mixin.py:190} INFO - Task:<Task(PythonOperator): transform_csv_to_fhir> dag:<DAG: csv_to_fhir_pipeline> dagrun:<DagRun csv_to_fhir_pipeline @ 2025-04-17 16:27:40.334621+00:00: manual__2025-04-17T16:27:40.334621+00:00, state:running, queued_at: 2025-04-17 16:27:40.379339+00:00. externally triggered: True>
[2025-04-17T16:27:46.141+0000] {logging_mixin.py:190} INFO - Failure caused by 3 validation errors for Claim
__root__ -> created
  field required (type=value_error.missing)
__root__ -> status
  field required (type=value_error.missing)
__root__ -> use
  field required (type=value_error.missing)
[2025-04-17T16:27:46.141+0000] {taskinstance.py:1226} INFO - Marking task as FAILED. dag_id=csv_to_fhir_pipeline, task_id=transform_csv_to_fhir, run_id=manual__2025-04-17T16:27:40.334621+00:00, execution_date=20250417T162740, start_date=20250417T162745, end_date=20250417T162746
[2025-04-17T16:27:46.179+0000] {taskinstance.py:341} INFO - ::group::Post task execution logs
[2025-04-17T16:27:46.182+0000] {standard_task_runner.py:124} ERROR - Failed to execute job 39 for task transform_csv_to_fhir (3 validation errors for Claim
__root__ -> created
  field required (type=value_error.missing)
__root__ -> status
  field required (type=value_error.missing)
__root__ -> use
  field required (type=value_error.missing); 487)
Traceback (most recent call last):
  File "/home/airflow/.local/lib/python3.12/site-packages/airflow/task/task_runner/standard_task_runner.py", line 117, in _start_by_fork
    ret = args.func(args, dag=self.dag)
          ^^^^^^^^^^^^^^^^^^^^^^^^^^^^^
  File "/home/airflow/.local/lib/python3.12/site-packages/airflow/cli/cli_config.py", line 49, in command
    return func(*args, **kwargs)
           ^^^^^^^^^^^^^^^^^^^^^
  File "/home/airflow/.local/lib/python3.12/site-packages/airflow/utils/cli.py", line 116, in wrapper
    return f(*args, **kwargs)
           ^^^^^^^^^^^^^^^^^^
  File "/home/airflow/.local/lib/python3.12/site-packages/airflow/cli/commands/task_command.py", line 483, in task_run
    task_return_code = _run_task_by_selected_method(args, _dag, ti)
                       ^^^^^^^^^^^^^^^^^^^^^^^^^^^^^^^^^^^^^^^^^^^^
  File "/home/airflow/.local/lib/python3.12/site-packages/airflow/cli/commands/task_command.py", line 256, in _run_task_by_selected_method
    return _run_raw_task(args, ti)
           ^^^^^^^^^^^^^^^^^^^^^^^
  File "/home/airflow/.local/lib/python3.12/site-packages/airflow/cli/commands/task_command.py", line 341, in _run_raw_task
    return ti._run_raw_task(
           ^^^^^^^^^^^^^^^^^
  File "/home/airflow/.local/lib/python3.12/site-packages/airflow/utils/session.py", line 97, in wrapper
    return func(*args, session=session, **kwargs)
           ^^^^^^^^^^^^^^^^^^^^^^^^^^^^^^^^^^^^^^
  File "/home/airflow/.local/lib/python3.12/site-packages/airflow/models/taskinstance.py", line 3006, in _run_raw_task
    return _run_raw_task(
           ^^^^^^^^^^^^^^
  File "/home/airflow/.local/lib/python3.12/site-packages/airflow/models/taskinstance.py", line 274, in _run_raw_task
    TaskInstance._execute_task_with_callbacks(
  File "/home/airflow/.local/lib/python3.12/site-packages/airflow/models/taskinstance.py", line 3161, in _execute_task_with_callbacks
    result = self._execute_task(context, task_orig)
             ^^^^^^^^^^^^^^^^^^^^^^^^^^^^^^^^^^^^^^
  File "/home/airflow/.local/lib/python3.12/site-packages/airflow/models/taskinstance.py", line 3185, in _execute_task
    return _execute_task(self, context, task_orig)
           ^^^^^^^^^^^^^^^^^^^^^^^^^^^^^^^^^^^^^^^
  File "/home/airflow/.local/lib/python3.12/site-packages/airflow/models/taskinstance.py", line 768, in _execute_task
    result = _execute_callable(context=context, **execute_callable_kwargs)
             ^^^^^^^^^^^^^^^^^^^^^^^^^^^^^^^^^^^^^^^^^^^^^^^^^^^^^^^^^^^^^
  File "/home/airflow/.local/lib/python3.12/site-packages/airflow/models/taskinstance.py", line 734, in _execute_callable
    return ExecutionCallableRunner(
           ^^^^^^^^^^^^^^^^^^^^^^^^
  File "/home/airflow/.local/lib/python3.12/site-packages/airflow/utils/operator_helpers.py", line 252, in run
    return self.func(*args, **kwargs)
           ^^^^^^^^^^^^^^^^^^^^^^^^^^
  File "/home/airflow/.local/lib/python3.12/site-packages/airflow/models/baseoperator.py", line 424, in wrapper
    return func(self, *args, **kwargs)
           ^^^^^^^^^^^^^^^^^^^^^^^^^^^
  File "/home/airflow/.local/lib/python3.12/site-packages/airflow/operators/python.py", line 238, in execute
    return_value = self.execute_callable()
                   ^^^^^^^^^^^^^^^^^^^^^^^
  File "/home/airflow/.local/lib/python3.12/site-packages/airflow/operators/python.py", line 256, in execute_callable
    return runner.run(*self.op_args, **self.op_kwargs)
           ^^^^^^^^^^^^^^^^^^^^^^^^^^^^^^^^^^^^^^^^^^^
  File "/home/airflow/.local/lib/python3.12/site-packages/airflow/utils/operator_helpers.py", line 252, in run
    return self.func(*args, **kwargs)
           ^^^^^^^^^^^^^^^^^^^^^^^^^^
  File "/opt/airflow/dags/scripts/transform_csv_to_fhir.py", line 87, in csv_to_fhir
    claim = Claim()
            ^^^^^^^
  File "/home/airflow/.local/lib/python3.12/site-packages/fhir/resources/core/fhirabstractmodel.py", line 105, in __init__
    BaseModel.__init__(__pydantic_self__, **data)
  File "/home/airflow/.local/lib/python3.12/site-packages/pydantic/v1/main.py", line 341, in __init__
    raise validation_error
pydantic.v1.error_wrappers.ValidationError: 3 validation errors for Claim
__root__ -> created
  field required (type=value_error.missing)
__root__ -> status
  field required (type=value_error.missing)
__root__ -> use
  field required (type=value_error.missing)
[2025-04-17T16:27:46.233+0000] {local_task_job_runner.py:266} INFO - Task exited with return code 1
[2025-04-17T16:27:46.248+0000] {taskinstance.py:3901} INFO - 0 downstream tasks scheduled from follow-on schedule check
[2025-04-17T16:27:46.250+0000] {local_task_job_runner.py:245} INFO - ::endgroup::
