[2025-04-16T21:01:59.093+0000] {local_task_job_runner.py:123} INFO - ::group::Pre task execution logs
[2025-04-16T21:01:59.116+0000] {taskinstance.py:2614} INFO - Dependencies all met for dep_context=non-requeueable deps ti=<TaskInstance: csv_to_fhir_pipeline.transform_csv_to_fhir manual__2025-04-16T21:01:54.277466+00:00 [queued]>
[2025-04-16T21:01:59.130+0000] {taskinstance.py:2614} INFO - Dependencies all met for dep_context=requeueable deps ti=<TaskInstance: csv_to_fhir_pipeline.transform_csv_to_fhir manual__2025-04-16T21:01:54.277466+00:00 [queued]>
[2025-04-16T21:01:59.131+0000] {taskinstance.py:2867} INFO - Starting attempt 1 of 1
[2025-04-16T21:01:59.157+0000] {taskinstance.py:2890} INFO - Executing <Task(PythonOperator): transform_csv_to_fhir> on 2025-04-16 21:01:54.277466+00:00
[2025-04-16T21:01:59.168+0000] {warnings.py:112} WARNING - /home/***/.local/lib/python3.12/site-packages/***/task/task_runner/standard_task_runner.py:70: DeprecationWarning: This process (pid=142) is multi-threaded, use of fork() may lead to deadlocks in the child.
  pid = os.fork()

[2025-04-16T21:01:59.169+0000] {standard_task_runner.py:104} INFO - Running: ['***', 'tasks', 'run', 'csv_to_fhir_pipeline', 'transform_csv_to_fhir', 'manual__2025-04-16T21:01:54.277466+00:00', '--job-id', '3', '--raw', '--subdir', 'DAGS_FOLDER/csv_to_fhir_dag.py', '--cfg-path', '/tmp/tmpeqhzi426']
[2025-04-16T21:01:59.171+0000] {standard_task_runner.py:72} INFO - Started process 151 to run task
[2025-04-16T21:01:59.171+0000] {standard_task_runner.py:105} INFO - Job 3: Subtask transform_csv_to_fhir
[2025-04-16T21:01:59.286+0000] {task_command.py:467} INFO - Running <TaskInstance: csv_to_fhir_pipeline.transform_csv_to_fhir manual__2025-04-16T21:01:54.277466+00:00 [running]> on host ad8bb0ecaf47
[2025-04-16T21:01:59.391+0000] {taskinstance.py:3134} INFO - Exporting env vars: AIRFLOW_CTX_DAG_OWNER='***' AIRFLOW_CTX_DAG_ID='csv_to_fhir_pipeline' AIRFLOW_CTX_TASK_ID='transform_csv_to_fhir' AIRFLOW_CTX_EXECUTION_DATE='2025-04-16T21:01:54.277466+00:00' AIRFLOW_CTX_TRY_NUMBER='1' AIRFLOW_CTX_DAG_RUN_ID='manual__2025-04-16T21:01:54.277466+00:00'
[2025-04-16T21:01:59.394+0000] {logging_mixin.py:190} INFO - Task instance is in running state
[2025-04-16T21:01:59.395+0000] {logging_mixin.py:190} INFO -  Previous state of the Task instance: queued
[2025-04-16T21:01:59.396+0000] {logging_mixin.py:190} INFO - Current task name:transform_csv_to_fhir state:running start_date:2025-04-16 21:01:59.117972+00:00
[2025-04-16T21:01:59.396+0000] {logging_mixin.py:190} INFO - Dag name:csv_to_fhir_pipeline and current dag run status:running
[2025-04-16T21:01:59.397+0000] {taskinstance.py:732} INFO - ::endgroup::
[2025-04-16T21:01:59.402+0000] {taskinstance.py:3313} ERROR - Task failed with exception
Traceback (most recent call last):
  File "/home/airflow/.local/lib/python3.12/site-packages/airflow/models/taskinstance.py", line 768, in _execute_task
    result = _execute_callable(context=context, **execute_callable_kwargs)
             ^^^^^^^^^^^^^^^^^^^^^^^^^^^^^^^^^^^^^^^^^^^^^^^^^^^^^^^^^^^^^
  File "/home/airflow/.local/lib/python3.12/site-packages/airflow/models/taskinstance.py", line 734, in _execute_callable
    return ExecutionCallableRunner(
           ^^^^^^^^^^^^^^^^^^^^^^^^
  File "/home/airflow/.local/lib/python3.12/site-packages/airflow/utils/operator_helpers.py", line 252, in run
    return self.func(*args, **kwargs)
           ^^^^^^^^^^^^^^^^^^^^^^^^^^
  File "/home/airflow/.local/lib/python3.12/site-packages/airflow/models/baseoperator.py", line 424, in wrapper
    return func(self, *args, **kwargs)
           ^^^^^^^^^^^^^^^^^^^^^^^^^^^
  File "/home/airflow/.local/lib/python3.12/site-packages/airflow/operators/python.py", line 238, in execute
    return_value = self.execute_callable()
                   ^^^^^^^^^^^^^^^^^^^^^^^
  File "/home/airflow/.local/lib/python3.12/site-packages/airflow/operators/python.py", line 256, in execute_callable
    return runner.run(*self.op_args, **self.op_kwargs)
           ^^^^^^^^^^^^^^^^^^^^^^^^^^^^^^^^^^^^^^^^^^^
  File "/home/airflow/.local/lib/python3.12/site-packages/airflow/utils/operator_helpers.py", line 252, in run
    return self.func(*args, **kwargs)
           ^^^^^^^^^^^^^^^^^^^^^^^^^^
  File "/opt/airflow/dags/scripts/transform_csv_to_fhir.py", line 18, in csv_to_fhir
    df = pd.read_csv(input_path)
         ^^^^^^^^^^^^^^^^^^^^^^^
  File "/home/airflow/.local/lib/python3.12/site-packages/pandas/io/parsers/readers.py", line 912, in read_csv
    return _read(filepath_or_buffer, kwds)
           ^^^^^^^^^^^^^^^^^^^^^^^^^^^^^^^
  File "/home/airflow/.local/lib/python3.12/site-packages/pandas/io/parsers/readers.py", line 577, in _read
    parser = TextFileReader(filepath_or_buffer, **kwds)
             ^^^^^^^^^^^^^^^^^^^^^^^^^^^^^^^^^^^^^^^^^^
  File "/home/airflow/.local/lib/python3.12/site-packages/pandas/io/parsers/readers.py", line 1407, in __init__
    self._engine = self._make_engine(f, self.engine)
                   ^^^^^^^^^^^^^^^^^^^^^^^^^^^^^^^^^
  File "/home/airflow/.local/lib/python3.12/site-packages/pandas/io/parsers/readers.py", line 1661, in _make_engine
    self.handles = get_handle(
                   ^^^^^^^^^^^
  File "/home/airflow/.local/lib/python3.12/site-packages/pandas/io/common.py", line 859, in get_handle
    handle = open(
             ^^^^^
FileNotFoundError: [Errno 2] No such file or directory: '/opt/airflow/data/input/healthcare_data.csv'
[2025-04-16T21:01:59.425+0000] {logging_mixin.py:190} INFO - Task instance in failure state
[2025-04-16T21:01:59.426+0000] {logging_mixin.py:190} INFO - Task start:2025-04-16 21:01:59.117972+00:00 end:2025-04-16 21:01:59.424583+00:00 duration:0.306611
[2025-04-16T21:01:59.426+0000] {logging_mixin.py:190} INFO - Task:<Task(PythonOperator): transform_csv_to_fhir> dag:<DAG: csv_to_fhir_pipeline> dagrun:<DagRun csv_to_fhir_pipeline @ 2025-04-16 21:01:54.277466+00:00: manual__2025-04-16T21:01:54.277466+00:00, state:running, queued_at: 2025-04-16 21:01:54.299265+00:00. externally triggered: True>
[2025-04-16T21:01:59.427+0000] {logging_mixin.py:190} INFO - Failure caused by [Errno 2] No such file or directory: '/opt/***/data/input/healthcare_data.csv'
[2025-04-16T21:01:59.428+0000] {taskinstance.py:1226} INFO - Marking task as FAILED. dag_id=csv_to_fhir_pipeline, task_id=transform_csv_to_fhir, run_id=manual__2025-04-16T21:01:54.277466+00:00, execution_date=20250416T210154, start_date=20250416T210159, end_date=20250416T210159
[2025-04-16T21:01:59.464+0000] {taskinstance.py:341} INFO - ::group::Post task execution logs
[2025-04-16T21:01:59.465+0000] {standard_task_runner.py:124} ERROR - Failed to execute job 3 for task transform_csv_to_fhir ([Errno 2] No such file or directory: '/opt/airflow/data/input/healthcare_data.csv'; 151)
Traceback (most recent call last):
  File "/home/airflow/.local/lib/python3.12/site-packages/airflow/task/task_runner/standard_task_runner.py", line 117, in _start_by_fork
    ret = args.func(args, dag=self.dag)
          ^^^^^^^^^^^^^^^^^^^^^^^^^^^^^
  File "/home/airflow/.local/lib/python3.12/site-packages/airflow/cli/cli_config.py", line 49, in command
    return func(*args, **kwargs)
           ^^^^^^^^^^^^^^^^^^^^^
  File "/home/airflow/.local/lib/python3.12/site-packages/airflow/utils/cli.py", line 116, in wrapper
    return f(*args, **kwargs)
           ^^^^^^^^^^^^^^^^^^
  File "/home/airflow/.local/lib/python3.12/site-packages/airflow/cli/commands/task_command.py", line 483, in task_run
    task_return_code = _run_task_by_selected_method(args, _dag, ti)
                       ^^^^^^^^^^^^^^^^^^^^^^^^^^^^^^^^^^^^^^^^^^^^
  File "/home/airflow/.local/lib/python3.12/site-packages/airflow/cli/commands/task_command.py", line 256, in _run_task_by_selected_method
    return _run_raw_task(args, ti)
           ^^^^^^^^^^^^^^^^^^^^^^^
  File "/home/airflow/.local/lib/python3.12/site-packages/airflow/cli/commands/task_command.py", line 341, in _run_raw_task
    return ti._run_raw_task(
           ^^^^^^^^^^^^^^^^^
  File "/home/airflow/.local/lib/python3.12/site-packages/airflow/utils/session.py", line 97, in wrapper
    return func(*args, session=session, **kwargs)
           ^^^^^^^^^^^^^^^^^^^^^^^^^^^^^^^^^^^^^^
  File "/home/airflow/.local/lib/python3.12/site-packages/airflow/models/taskinstance.py", line 3006, in _run_raw_task
    return _run_raw_task(
           ^^^^^^^^^^^^^^
  File "/home/airflow/.local/lib/python3.12/site-packages/airflow/models/taskinstance.py", line 274, in _run_raw_task
    TaskInstance._execute_task_with_callbacks(
  File "/home/airflow/.local/lib/python3.12/site-packages/airflow/models/taskinstance.py", line 3161, in _execute_task_with_callbacks
    result = self._execute_task(context, task_orig)
             ^^^^^^^^^^^^^^^^^^^^^^^^^^^^^^^^^^^^^^
  File "/home/airflow/.local/lib/python3.12/site-packages/airflow/models/taskinstance.py", line 3185, in _execute_task
    return _execute_task(self, context, task_orig)
           ^^^^^^^^^^^^^^^^^^^^^^^^^^^^^^^^^^^^^^^
  File "/home/airflow/.local/lib/python3.12/site-packages/airflow/models/taskinstance.py", line 768, in _execute_task
    result = _execute_callable(context=context, **execute_callable_kwargs)
             ^^^^^^^^^^^^^^^^^^^^^^^^^^^^^^^^^^^^^^^^^^^^^^^^^^^^^^^^^^^^^
  File "/home/airflow/.local/lib/python3.12/site-packages/airflow/models/taskinstance.py", line 734, in _execute_callable
    return ExecutionCallableRunner(
           ^^^^^^^^^^^^^^^^^^^^^^^^
  File "/home/airflow/.local/lib/python3.12/site-packages/airflow/utils/operator_helpers.py", line 252, in run
    return self.func(*args, **kwargs)
           ^^^^^^^^^^^^^^^^^^^^^^^^^^
  File "/home/airflow/.local/lib/python3.12/site-packages/airflow/models/baseoperator.py", line 424, in wrapper
    return func(self, *args, **kwargs)
           ^^^^^^^^^^^^^^^^^^^^^^^^^^^
  File "/home/airflow/.local/lib/python3.12/site-packages/airflow/operators/python.py", line 238, in execute
    return_value = self.execute_callable()
                   ^^^^^^^^^^^^^^^^^^^^^^^
  File "/home/airflow/.local/lib/python3.12/site-packages/airflow/operators/python.py", line 256, in execute_callable
    return runner.run(*self.op_args, **self.op_kwargs)
           ^^^^^^^^^^^^^^^^^^^^^^^^^^^^^^^^^^^^^^^^^^^
  File "/home/airflow/.local/lib/python3.12/site-packages/airflow/utils/operator_helpers.py", line 252, in run
    return self.func(*args, **kwargs)
           ^^^^^^^^^^^^^^^^^^^^^^^^^^
  File "/opt/airflow/dags/scripts/transform_csv_to_fhir.py", line 18, in csv_to_fhir
    df = pd.read_csv(input_path)
         ^^^^^^^^^^^^^^^^^^^^^^^
  File "/home/airflow/.local/lib/python3.12/site-packages/pandas/io/parsers/readers.py", line 912, in read_csv
    return _read(filepath_or_buffer, kwds)
           ^^^^^^^^^^^^^^^^^^^^^^^^^^^^^^^
  File "/home/airflow/.local/lib/python3.12/site-packages/pandas/io/parsers/readers.py", line 577, in _read
    parser = TextFileReader(filepath_or_buffer, **kwds)
             ^^^^^^^^^^^^^^^^^^^^^^^^^^^^^^^^^^^^^^^^^^
  File "/home/airflow/.local/lib/python3.12/site-packages/pandas/io/parsers/readers.py", line 1407, in __init__
    self._engine = self._make_engine(f, self.engine)
                   ^^^^^^^^^^^^^^^^^^^^^^^^^^^^^^^^^
  File "/home/airflow/.local/lib/python3.12/site-packages/pandas/io/parsers/readers.py", line 1661, in _make_engine
    self.handles = get_handle(
                   ^^^^^^^^^^^
  File "/home/airflow/.local/lib/python3.12/site-packages/pandas/io/common.py", line 859, in get_handle
    handle = open(
             ^^^^^
FileNotFoundError: [Errno 2] No such file or directory: '/opt/airflow/data/input/healthcare_data.csv'
[2025-04-16T21:01:59.514+0000] {local_task_job_runner.py:266} INFO - Task exited with return code 1
[2025-04-16T21:01:59.532+0000] {taskinstance.py:3901} INFO - 0 downstream tasks scheduled from follow-on schedule check
[2025-04-16T21:01:59.535+0000] {local_task_job_runner.py:245} INFO - ::endgroup::
