[2025-04-17T02:40:46.921+0000] {local_task_job_runner.py:123} INFO - ::group::Pre task execution logs
[2025-04-17T02:40:46.937+0000] {taskinstance.py:2614} INFO - Dependencies all met for dep_context=non-requeueable deps ti=<TaskInstance: csv_to_fhir_pipeline.transform_csv_to_fhir manual__2025-04-17T02:40:44.321562+00:00 [queued]>
[2025-04-17T02:40:46.947+0000] {taskinstance.py:2614} INFO - Dependencies all met for dep_context=requeueable deps ti=<TaskInstance: csv_to_fhir_pipeline.transform_csv_to_fhir manual__2025-04-17T02:40:44.321562+00:00 [queued]>
[2025-04-17T02:40:46.948+0000] {taskinstance.py:2867} INFO - Starting attempt 1 of 1
[2025-04-17T02:40:46.963+0000] {taskinstance.py:2890} INFO - Executing <Task(PythonOperator): transform_csv_to_fhir> on 2025-04-17 02:40:44.321562+00:00
[2025-04-17T02:40:46.971+0000] {warnings.py:112} WARNING - /home/***/.local/lib/python3.12/site-packages/***/task/task_runner/standard_task_runner.py:70: DeprecationWarning: This process (pid=876) is multi-threaded, use of fork() may lead to deadlocks in the child.
  pid = os.fork()

[2025-04-17T02:40:46.973+0000] {standard_task_runner.py:72} INFO - Started process 878 to run task
[2025-04-17T02:40:46.973+0000] {standard_task_runner.py:104} INFO - Running: ['***', 'tasks', 'run', 'csv_to_fhir_pipeline', 'transform_csv_to_fhir', 'manual__2025-04-17T02:40:44.321562+00:00', '--job-id', '15', '--raw', '--subdir', 'DAGS_FOLDER/csv_to_fhir_dag.py', '--cfg-path', '/tmp/tmpg15p7ubu']
[2025-04-17T02:40:46.975+0000] {standard_task_runner.py:105} INFO - Job 15: Subtask transform_csv_to_fhir
[2025-04-17T02:40:47.017+0000] {task_command.py:467} INFO - Running <TaskInstance: csv_to_fhir_pipeline.transform_csv_to_fhir manual__2025-04-17T02:40:44.321562+00:00 [running]> on host 1e132ad692d9
[2025-04-17T02:40:47.095+0000] {taskinstance.py:3134} INFO - Exporting env vars: AIRFLOW_CTX_DAG_OWNER='***' AIRFLOW_CTX_DAG_ID='csv_to_fhir_pipeline' AIRFLOW_CTX_TASK_ID='transform_csv_to_fhir' AIRFLOW_CTX_EXECUTION_DATE='2025-04-17T02:40:44.321562+00:00' AIRFLOW_CTX_TRY_NUMBER='1' AIRFLOW_CTX_DAG_RUN_ID='manual__2025-04-17T02:40:44.321562+00:00'
[2025-04-17T02:40:47.096+0000] {logging_mixin.py:190} INFO - Task instance is in running state
[2025-04-17T02:40:47.097+0000] {logging_mixin.py:190} INFO -  Previous state of the Task instance: queued
[2025-04-17T02:40:47.098+0000] {logging_mixin.py:190} INFO - Current task name:transform_csv_to_fhir state:running start_date:2025-04-17 02:40:46.938218+00:00
[2025-04-17T02:40:47.099+0000] {logging_mixin.py:190} INFO - Dag name:csv_to_fhir_pipeline and current dag run status:running
[2025-04-17T02:40:47.099+0000] {taskinstance.py:732} INFO - ::endgroup::
[2025-04-17T02:40:49.468+0000] {warnings.py:112} WARNING - /opt/***/dags/scripts/transform_csv_to_fhir.py:18: DtypeWarning: Columns (0,32,37,40) have mixed types. Specify dtype option on import or set low_memory=False.
  df = pd.read_csv(input_path, encoding='latin1')

[2025-04-17T02:40:50.310+0000] {taskinstance.py:3313} ERROR - Task failed with exception
Traceback (most recent call last):
  File "/home/airflow/.local/lib/python3.12/site-packages/airflow/models/taskinstance.py", line 768, in _execute_task
    result = _execute_callable(context=context, **execute_callable_kwargs)
             ^^^^^^^^^^^^^^^^^^^^^^^^^^^^^^^^^^^^^^^^^^^^^^^^^^^^^^^^^^^^^
  File "/home/airflow/.local/lib/python3.12/site-packages/airflow/models/taskinstance.py", line 734, in _execute_callable
    return ExecutionCallableRunner(
           ^^^^^^^^^^^^^^^^^^^^^^^^
  File "/home/airflow/.local/lib/python3.12/site-packages/airflow/utils/operator_helpers.py", line 252, in run
    return self.func(*args, **kwargs)
           ^^^^^^^^^^^^^^^^^^^^^^^^^^
  File "/home/airflow/.local/lib/python3.12/site-packages/airflow/models/baseoperator.py", line 424, in wrapper
    return func(self, *args, **kwargs)
           ^^^^^^^^^^^^^^^^^^^^^^^^^^^
  File "/home/airflow/.local/lib/python3.12/site-packages/airflow/operators/python.py", line 238, in execute
    return_value = self.execute_callable()
                   ^^^^^^^^^^^^^^^^^^^^^^^
  File "/home/airflow/.local/lib/python3.12/site-packages/airflow/operators/python.py", line 256, in execute_callable
    return runner.run(*self.op_args, **self.op_kwargs)
           ^^^^^^^^^^^^^^^^^^^^^^^^^^^^^^^^^^^^^^^^^^^
  File "/home/airflow/.local/lib/python3.12/site-packages/airflow/utils/operator_helpers.py", line 252, in run
    return self.func(*args, **kwargs)
           ^^^^^^^^^^^^^^^^^^^^^^^^^^
  File "/opt/airflow/dags/scripts/transform_csv_to_fhir.py", line 72, in csv_to_fhir
    encounter.diagnosis = [{
    ^^^^^^^^^^^^^^^^^^^
  File "/home/airflow/.local/lib/python3.12/site-packages/pydantic/v1/main.py", line 384, in __setattr__
    raise ValidationError([error_], self.__class__)
pydantic.v1.error_wrappers.ValidationError: 2 validation errors for Encounter
diagnosis -> 0 -> condition
  value is not a valid list (type=type_error.list)
diagnosis -> 0 -> use
  value is not a valid list (type=type_error.list)
[2025-04-17T02:40:50.325+0000] {logging_mixin.py:190} INFO - Task instance in failure state
[2025-04-17T02:40:50.326+0000] {logging_mixin.py:190} INFO - Task start:2025-04-17 02:40:46.938218+00:00 end:2025-04-17 02:40:50.325455+00:00 duration:3.387237
[2025-04-17T02:40:50.327+0000] {logging_mixin.py:190} INFO - Task:<Task(PythonOperator): transform_csv_to_fhir> dag:<DAG: csv_to_fhir_pipeline> dagrun:<DagRun csv_to_fhir_pipeline @ 2025-04-17 02:40:44.321562+00:00: manual__2025-04-17T02:40:44.321562+00:00, state:running, queued_at: 2025-04-17 02:40:44.373913+00:00. externally triggered: True>
[2025-04-17T02:40:50.328+0000] {logging_mixin.py:190} INFO - Failure caused by 2 validation errors for Encounter
diagnosis -> 0 -> condition
  value is not a valid list (type=type_error.list)
diagnosis -> 0 -> use
  value is not a valid list (type=type_error.list)
[2025-04-17T02:40:50.329+0000] {taskinstance.py:1226} INFO - Marking task as FAILED. dag_id=csv_to_fhir_pipeline, task_id=transform_csv_to_fhir, run_id=manual__2025-04-17T02:40:44.321562+00:00, execution_date=20250417T024044, start_date=20250417T024046, end_date=20250417T024050
[2025-04-17T02:40:50.360+0000] {taskinstance.py:341} INFO - ::group::Post task execution logs
[2025-04-17T02:40:50.361+0000] {standard_task_runner.py:124} ERROR - Failed to execute job 15 for task transform_csv_to_fhir (2 validation errors for Encounter
diagnosis -> 0 -> condition
  value is not a valid list (type=type_error.list)
diagnosis -> 0 -> use
  value is not a valid list (type=type_error.list); 878)
Traceback (most recent call last):
  File "/home/airflow/.local/lib/python3.12/site-packages/airflow/task/task_runner/standard_task_runner.py", line 117, in _start_by_fork
    ret = args.func(args, dag=self.dag)
          ^^^^^^^^^^^^^^^^^^^^^^^^^^^^^
  File "/home/airflow/.local/lib/python3.12/site-packages/airflow/cli/cli_config.py", line 49, in command
    return func(*args, **kwargs)
           ^^^^^^^^^^^^^^^^^^^^^
  File "/home/airflow/.local/lib/python3.12/site-packages/airflow/utils/cli.py", line 116, in wrapper
    return f(*args, **kwargs)
           ^^^^^^^^^^^^^^^^^^
  File "/home/airflow/.local/lib/python3.12/site-packages/airflow/cli/commands/task_command.py", line 483, in task_run
    task_return_code = _run_task_by_selected_method(args, _dag, ti)
                       ^^^^^^^^^^^^^^^^^^^^^^^^^^^^^^^^^^^^^^^^^^^^
  File "/home/airflow/.local/lib/python3.12/site-packages/airflow/cli/commands/task_command.py", line 256, in _run_task_by_selected_method
    return _run_raw_task(args, ti)
           ^^^^^^^^^^^^^^^^^^^^^^^
  File "/home/airflow/.local/lib/python3.12/site-packages/airflow/cli/commands/task_command.py", line 341, in _run_raw_task
    return ti._run_raw_task(
           ^^^^^^^^^^^^^^^^^
  File "/home/airflow/.local/lib/python3.12/site-packages/airflow/utils/session.py", line 97, in wrapper
    return func(*args, session=session, **kwargs)
           ^^^^^^^^^^^^^^^^^^^^^^^^^^^^^^^^^^^^^^
  File "/home/airflow/.local/lib/python3.12/site-packages/airflow/models/taskinstance.py", line 3006, in _run_raw_task
    return _run_raw_task(
           ^^^^^^^^^^^^^^
  File "/home/airflow/.local/lib/python3.12/site-packages/airflow/models/taskinstance.py", line 274, in _run_raw_task
    TaskInstance._execute_task_with_callbacks(
  File "/home/airflow/.local/lib/python3.12/site-packages/airflow/models/taskinstance.py", line 3161, in _execute_task_with_callbacks
    result = self._execute_task(context, task_orig)
             ^^^^^^^^^^^^^^^^^^^^^^^^^^^^^^^^^^^^^^
  File "/home/airflow/.local/lib/python3.12/site-packages/airflow/models/taskinstance.py", line 3185, in _execute_task
    return _execute_task(self, context, task_orig)
           ^^^^^^^^^^^^^^^^^^^^^^^^^^^^^^^^^^^^^^^
  File "/home/airflow/.local/lib/python3.12/site-packages/airflow/models/taskinstance.py", line 768, in _execute_task
    result = _execute_callable(context=context, **execute_callable_kwargs)
             ^^^^^^^^^^^^^^^^^^^^^^^^^^^^^^^^^^^^^^^^^^^^^^^^^^^^^^^^^^^^^
  File "/home/airflow/.local/lib/python3.12/site-packages/airflow/models/taskinstance.py", line 734, in _execute_callable
    return ExecutionCallableRunner(
           ^^^^^^^^^^^^^^^^^^^^^^^^
  File "/home/airflow/.local/lib/python3.12/site-packages/airflow/utils/operator_helpers.py", line 252, in run
    return self.func(*args, **kwargs)
           ^^^^^^^^^^^^^^^^^^^^^^^^^^
  File "/home/airflow/.local/lib/python3.12/site-packages/airflow/models/baseoperator.py", line 424, in wrapper
    return func(self, *args, **kwargs)
           ^^^^^^^^^^^^^^^^^^^^^^^^^^^
  File "/home/airflow/.local/lib/python3.12/site-packages/airflow/operators/python.py", line 238, in execute
    return_value = self.execute_callable()
                   ^^^^^^^^^^^^^^^^^^^^^^^
  File "/home/airflow/.local/lib/python3.12/site-packages/airflow/operators/python.py", line 256, in execute_callable
    return runner.run(*self.op_args, **self.op_kwargs)
           ^^^^^^^^^^^^^^^^^^^^^^^^^^^^^^^^^^^^^^^^^^^
  File "/home/airflow/.local/lib/python3.12/site-packages/airflow/utils/operator_helpers.py", line 252, in run
    return self.func(*args, **kwargs)
           ^^^^^^^^^^^^^^^^^^^^^^^^^^
  File "/opt/airflow/dags/scripts/transform_csv_to_fhir.py", line 72, in csv_to_fhir
    encounter.diagnosis = [{
    ^^^^^^^^^^^^^^^^^^^
  File "/home/airflow/.local/lib/python3.12/site-packages/pydantic/v1/main.py", line 384, in __setattr__
    raise ValidationError([error_], self.__class__)
pydantic.v1.error_wrappers.ValidationError: 2 validation errors for Encounter
diagnosis -> 0 -> condition
  value is not a valid list (type=type_error.list)
diagnosis -> 0 -> use
  value is not a valid list (type=type_error.list)
[2025-04-17T02:40:50.404+0000] {local_task_job_runner.py:266} INFO - Task exited with return code 1
[2025-04-17T02:40:50.422+0000] {taskinstance.py:3901} INFO - 0 downstream tasks scheduled from follow-on schedule check
[2025-04-17T02:40:50.426+0000] {local_task_job_runner.py:245} INFO - ::endgroup::
